<?xml version="1.0" ?>
<!-- =================================================================================== -->
<!-- |    This document was autogenerated by xacro from open_manipulator_with_tb3_waffle_pi.urdf.xacro | -->
<!-- |    EDITING THIS FILE BY HAND IS NOT RECOMMENDED                                 | -->
<!-- =================================================================================== -->
<!-- Open_Manipulator Chain -->
<robot name="om_with_tb3" xmlns:xacro="http://ros.org/wiki/xacro">
  <!-- Init colour -->
  <material name="black">
    <color rgba="0.0 0.0 0.0 1.0"/>
  </material>
  <material name="dark">
    <color rgba="0.3 0.3 0.3 1.0"/>
  </material>
  <material name="light_black">
    <color rgba="0.4 0.4 0.4 1.0"/>
  </material>
  <material name="blue">
    <color rgba="0.0 0.0 0.8 1.0"/>
  </material>
  <material name="green">
    <color rgba="0.0 0.8 0.0 1.0"/>
  </material>
  <material name="grey">
    <color rgba="0.5 0.5 0.5 1.0"/>
  </material>
  <material name="orange">
    <color rgba="1.0 0.423529411765 0.0392156862745 1.0"/>
  </material>
  <material name="brown">
    <color rgba="0.870588235294 0.811764705882 0.764705882353 1.0"/>
  </material>
  <material name="red">
    <color rgba="0.8 0.0 0.0 1.0"/>
  </material>
  <material name="white">
    <color rgba="1.0 1.0 1.0 1.0"/>
  </material>
  
  <link name="base_link">
    <visual>
      <origin rpy="0 0 0" xyz="0 0 0.0"/>
      <geometry>
        <mesh filename="meshes/bases/waffle_pi_base_for_open_manipulator.stl" scale="0.001 0.001 0.001"/>
      </geometry>
      <material name="light_black"/>
    </visual>
    <collision>
      <origin rpy="0 0 0" xyz="0.0 0 0.047"/>
      <geometry>
        <box size="0.266 0.266 0.094"/>
      </geometry>
    </collision>
    <inertial>
      <origin rpy="0 0 0" xyz="0.0 0 -.1"/>
      <!-- <origin rpy="0 0 0" xyz="0 0 0"/> -->
      <mass value="10.3729096e+00"/>
      <!-- <mass value="1.3729096e+00"/> -->
      <inertia ixx="8.7002718e-03" ixy="-4.7576583e-05" ixz="1.1160499e-04" iyy="8.6195418e-03" iyz="-3.5422299e-06" izz="1.4612727e-02"/>
    </inertial>
  </link>
  <!-- <gazebo reference="base_link"> -->
  <!--   <material>Gazebo/DarkGrey</material> -->
  <!-- </gazebo> -->

  <joint name="wheel_left_joint" type="continuous">
    <parent link="base_link"/>
    <child link="wheel_left_link"/>
    <origin rpy="-1.5707963267948966 0 0" xyz=".08 0.144 0.0"/>
    <axis xyz="0 0 1"/>
  </joint>
  <link name="wheel_left_link">
    <contact>
      <lateral_friction value="1.0"/>
      <!-- <rolling_friction value="0.0"/> -->
      <stiffness value="500000"/>
      <damping value="10"/>
    </contact>
    <visual>
      <origin rpy="1.5707963267948966 0 0" xyz="0 0 0"/>
      <geometry>
        <mesh filename="meshes/wheels/left_tire.stl" scale="0.001 0.001 0.001"/>
      </geometry>
      <material name="dark"/>
    </visual>
    <collision>
      <origin rpy="0 0 0" xyz="0 0 0"/>
      <geometry>
	<cylinder length="0.018" radius="0.033"/>
      </geometry>
    </collision>
    <inertial>
      <origin xyz="0 0 0"/>
      <mass value="2.8498940e-00"/>
      <inertia ixx="1.1175580e-05" ixy="-4.2369783e-11" ixz="-5.9381719e-09" iyy="1.1192413e-05" iyz="-1.4400107e-11" izz="2.0712558e-05"/>
    </inertial>
  </link>
  <transmission name="wheel_left_trans">
    <type>transmission_interface/SimpleTransmission</type>
    <joint name="wheel_left_joint">
      <hardwareInterface>hardware_interface/VelocityJointInterface</hardwareInterface>
    </joint>
    <actuator name="wheel_left_actuator">
      <mechanicalReduction>1</mechanicalReduction>
    </actuator>
  </transmission>
  
  <!-- <gazebo reference="wheel_left_link"> -->
  <!--   <mu1>0.1</mu1> -->
  <!--   <mu2>0.1</mu2> -->
  <!--   <kp>500000.0</kp> -->
  <!--   <kd>10.0</kd> -->
  <!--   <minDepth>0.001</minDepth> -->
  <!--   <maxVel>0.1</maxVel> -->
  <!--   <fdir1>1 0 0</fdir1> -->
  <!--   <material>Gazebo/FlatBlack</material> -->
  <!-- </gazebo> -->
    
  <joint name="wheel_right_joint" type="continuous">
    <parent link="base_link"/>
    <child link="wheel_right_link"/>
    <origin rpy="-1.5707963267948966 0 0" xyz=".08 -0.144 0.0"/>
    <axis xyz="0 0 1"/>
  </joint>
  <link name="wheel_right_link">
    <contact>
      <lateral_friction value="1.0"/>
      <!-- <rolling_friction value="0.0"/> -->
      <stiffness value="500000"/>
      <damping value="10"/>
    </contact>
    <visual>
      <origin rpy="1.5707963267948966 0 0" xyz="0 0 0"/>
      <geometry>
        <mesh filename="meshes/wheels/right_tire.stl" scale="0.001 0.001 0.001"/>
      </geometry>
      <material name="dark"/>
    </visual>
    <collision>
      <origin rpy="0 0 0" xyz="0 0 0"/>
      <geometry>
        <cylinder length="0.018" radius="0.033"/>
      </geometry>
    </collision>
    <inertial>
      <origin xyz="0 0 0"/>
      <mass value="2.8498940e-00"/>
      <inertia ixx="1.1175580e-05" ixy="-4.2369783e-11" ixz="-5.9381719e-09" iyy="1.1192413e-05" iyz="-1.4400107e-11" izz="2.0712558e-05"/>
    </inertial>
  </link>
  <transmission name="wheel_right_trans">
    <type>transmission_interface/SimpleTransmission</type>
    <joint name="wheel_right_joint">
      <hardwareInterface>hardware_interface/VelocityJointInterface</hardwareInterface>
    </joint>
    <actuator name="wheel_right_actuator">
      <mechanicalReduction>1</mechanicalReduction>
    </actuator>
  </transmission>
  
  <!-- <gazebo reference="wheel_right_link"> -->
  <!--   <mu1>0.1</mu1> -->
  <!--   <mu2>0.1</mu2> -->
  <!--   <kp>500000.0</kp> -->
  <!--   <kd>10.0</kd> -->
  <!--   <minDepth>0.001</minDepth> -->
  <!--   <maxVel>0.1</maxVel> -->
  <!--   <fdir1>1 0 0</fdir1> -->
  <!--   <material>Gazebo/FlatBlack</material> -->
  <!-- </gazebo> -->

  <joint name="wheel_left_rear_joint" type="continuous">
    <parent link="base_link"/>
    <child link="wheel_left_rear_link"/>
    <origin rpy="-1.5707963267948966 0 0" xyz="-.08 0.144 0.0"/>
    <axis xyz="0 0 1"/>
  </joint>
  <link name="wheel_left_rear_link">
    <contact>
      <lateral_friction value="1.0"/>
      <!-- <rolling_friction value="0.0"/> -->
      <stiffness value="500000"/>
      <damping value="10"/>
    </contact>
    <visual>
      <origin rpy="1.5707963267948966 0 0" xyz="0 0 0"/>
      <geometry>
        <mesh filename="meshes/wheels/left_tire.stl" scale="0.001 0.001 0.001"/>
      </geometry>
      <material name="dark"/>
    </visual>
    <collision>
      <origin rpy="0 0 0" xyz="0 0 0"/>
      <geometry>
	<cylinder length="0.018" radius="0.033"/>
      </geometry>
    </collision>
    <inertial>
      <origin xyz="0 0 0"/>
      <mass value="2.8498940e-00"/>
      <inertia ixx="1.1175580e-05" ixy="-4.2369783e-11" ixz="-5.9381719e-09" iyy="1.1192413e-05" iyz="-1.4400107e-11" izz="2.0712558e-05"/>
    </inertial>
  </link>
  <transmission name="wheel_left_rear_trans">
    <type>transmission_interface/SimpleTransmission</type>
    <joint name="wheel_left_rear_joint">
      <hardwareInterface>hardware_interface/VelocityJointInterface</hardwareInterface>
    </joint>
    <actuator name="wheel_left_rear_actuator">
      <mechanicalReduction>1</mechanicalReduction>
    </actuator>
  </transmission>
  
  <!-- <gazebo reference="wheel_left_link"> -->
  <!--   <mu1>0.1</mu1> -->
  <!--   <mu2>0.1</mu2> -->
  <!--   <kp>500000.0</kp> -->
  <!--   <kd>10.0</kd> -->
  <!--   <minDepth>0.001</minDepth> -->
  <!--   <maxVel>0.1</maxVel> -->
  <!--   <fdir1>1 0 0</fdir1> -->
  <!--   <material>Gazebo/FlatBlack</material> -->
  <!-- </gazebo> -->
    
  <joint name="wheel_right_rear_joint" type="continuous">
    <parent link="base_link"/>
    <child link="wheel_right_rear_link"/>
    <origin rpy="-1.5707963267948966 0 0" xyz="-.08 -0.144 0.0"/>
    <axis xyz="0 0 1"/>
  </joint>
  <link name="wheel_right_rear_link">
    <contact>
      <lateral_friction value="1.0"/>
      <!-- <rolling_friction value="0.0"/> -->
      <stiffness value="500000"/>
      <damping value="10"/>
    </contact>
    <visual>
      <origin rpy="1.5707963267948966 0 0" xyz="0 0 0"/>
      <geometry>
        <mesh filename="meshes/wheels/right_tire.stl" scale="0.001 0.001 0.001"/>
      </geometry>
      <material name="dark"/>
    </visual>
    <collision>
      <origin rpy="0 0 0" xyz="0 0.0 0"/>
      <geometry>
	<cylinder length="0.018" radius="0.033"/>
      </geometry>
    </collision>
    <inertial>
      <origin xyz="0 0 0"/>
      <mass value="2.8498940e-00"/>
      <inertia ixx="1.1175580e-05" ixy="-4.2369783e-11" ixz="-5.9381719e-09" iyy="1.1192413e-05" iyz="-1.4400107e-11" izz="2.0712558e-05"/>
    </inertial>
  </link>
  <transmission name="wheel_right_rear_trans">
    <type>transmission_interface/SimpleTransmission</type>
    <joint name="wheel_right_rear_joint">
      <hardwareInterface>hardware_interface/VelocityJointInterface</hardwareInterface>
    </joint>
    <actuator name="wheel_right_rear_actuator">
      <mechanicalReduction>1</mechanicalReduction>
    </actuator>
  </transmission>
    
  <!-- <joint name="imu_joint" type="fixed"> -->
  <!--   <parent link="base_link"/> -->
  <!--   <child link="imu_link"/> -->
  <!--   <origin rpy="0 0 0" xyz="0.0 0 0.068"/> -->
  <!-- </joint> -->
  <!-- <link name="imu_link"/> -->
  <joint name="scan_joint" type="fixed">
    <parent link="base_link"/>
    <child link="base_scan"/>
    <origin rpy="0 0 0" xyz="0.065 0 0.122"/>
  </joint>
  <link name="base_scan">
    <visual>
      <origin rpy="0 0 0" xyz="0 0 0.0"/>
      <geometry>
        <mesh filename="meshes/sensors/lds.stl" scale="0.001 0.001 0.001"/>
      </geometry>
      <material name="dark"/>
    </visual>
    <collision>
      <origin rpy="0 0 0" xyz="0.015 0 -0.0065"/>
      <geometry>
        <cylinder length="0.0315" radius="0.045"/>
      </geometry>
    </collision>
    <!-- <inertial> -->
    <!--   <mass value="0.114"/> -->
    <!--   <origin xyz="0 0 0"/> -->
    <!--   <inertia ixx="0.001" ixy="0.0" ixz="0.0" iyy="0.001" iyz="0.0" izz="0.001"/> -->
    <!-- </inertial> -->
  </link>
  <!-- <joint name="camera_joint" type="fixed"> -->
  <!--   <origin rpy="0 0 0" xyz="0.073 0 0.084"/> -->
  <!--   <parent link="base_link"/> -->
  <!--   <child link="camera_link"/> -->
  <!-- </joint> -->
  <!-- <link name="camera_link"> -->
  <!--   <collision> -->
  <!--     <origin rpy="0 0 0" xyz="0.005 0 0.013"/> -->
  <!--     <geometry> -->
  <!--       <box size="0.015 0.030 0.027"/> -->
  <!--     </geometry> -->
  <!--   </collision> -->
  <!-- </link> -->
  <!-- <joint name="camera_rgb_joint" type="fixed"> -->
  <!--   <origin rpy="0 0 0" xyz="0.003 0.011 0.009"/> -->
  <!--   <parent link="camera_link"/> -->
  <!--   <child link="camera_rgb_frame"/> -->
  <!-- </joint> -->
  <!-- <link name="camera_rgb_frame"/> -->
  <!-- <joint name="camera_rgb_optical_joint" type="fixed"> -->
  <!--   <origin rpy="-1.57 0 -1.57" xyz="0 0 0"/> -->
  <!--   <parent link="camera_rgb_frame"/> -->
  <!--   <child link="camera_rgb_optical_frame"/> -->
  <!-- </joint> -->
  <!-- <link name="camera_rgb_optical_frame"/> -->

    <!-- Basket fixed joint -->
  <joint name="basket_base_fixed" type="fixed">
    <origin rpy="0 0 0" xyz="-0.165 .0 .005"/>
    <parent link="base_link"/>
    <child link="basket"/>
  </joint>
  <!-- Basket -->
  <link name="basket">
    <visual>
      <origin rpy="0 0 0" xyz=".0 .11 .05"/>
      <geometry>
        <box size="0.085 0.005 0.1" />
      </geometry>
      <material name="grey"/>
    </visual>
    <visual>
      <origin rpy="0 0 0" xyz=".0 -.11 .05"/>
      <geometry>
        <box size="0.085 0.005 0.1" />
      </geometry>
      <material name="grey"/>
    </visual>
    <visual>
      <origin rpy="0 0 0" xyz=".04 .0 .05"/>
      <geometry>
        <box size="0.005 0.225 0.1" />
      </geometry>
      <material name="grey"/>
    </visual>
    <visual>
      <origin rpy="0 0 0" xyz="-.04 .0 .05"/>
      <geometry>
        <box size="0.005 0.225 0.1" />
      </geometry>
      <material name="grey"/>
    </visual>
    <visual>
      <origin rpy="0 0 0" xyz=".0 .0 .0"/>
      <geometry>
        <box size="0.085 0.225 0.005" />
      </geometry>
      <material name="grey"/>
    </visual>

    <collision>
      <origin rpy="0 0 0" xyz=".0 .11 .05"/>
      <geometry>
        <box size="0.085 0.005 0.1" />
      </geometry>
    </collision>
    <collision>
      <origin rpy="0 0 0" xyz=".0 -.11 .05"/>
      <geometry>
        <box size="0.085 0.005 0.1" />
      </geometry>
    </collision>
    <collision>
      <origin rpy="0 0 0" xyz=".04 .0 .05"/>
      <geometry>
        <box size="0.005 0.225 0.1" />
      </geometry>
    </collision>
    <collision>
      <origin rpy="0 0 0" xyz="-.04 .0 .05"/>
      <geometry>
        <box size="0.005 0.225 0.1" />
      </geometry>
    </collision>
    <collision>
      <origin rpy="0 0 0" xyz=".0 .0 .0"/>
      <geometry>
        <box size="0.085 0.225 0.005" />
      </geometry>
    </collision>
    <inertial>
      <origin xyz="3.0876154e-04 0.0000000e+00 -1.2176461e-04"/>
      <mass value="7.9119962e-06"/>
      <inertia ixx="1.2505234e-05" ixy="0.0" ixz="-1.7855208e-07" iyy="2.1898364e-05" iyz="0.0" izz="1.9267361e-05"/>
    </inertial>
  </link>
    
  <!-- Base fixed joint -->
  <joint name="base_fixed" type="fixed">
    <origin rpy="0 0 0" xyz="-.01 0.0 0.091"/>
    <parent link="base_link"/>
    <child link="link1"/>
  </joint>
  <!-- Link 1 -->
  <link name="link1">
    <visual>
      <origin rpy="0 0 0" xyz="0 0 0"/>
      <geometry>
        <mesh filename="meshes/chain_link1.stl" scale="0.001 0.001 0.001"/>
      </geometry>
      <material name="grey"/>
    </visual>
    <collision>
      <origin rpy="0 0 0" xyz="0 0 0"/>
      <geometry>
        <mesh filename="meshes/chain_link1.stl" scale="0.001 0.001 0.001"/>
      </geometry>
    </collision>
    <!--    <inertial>
      <origin xyz="0 0 0" />
      <mass value="0.082" />
      <inertia ixx="0.1" ixy="0.0" ixz="0.0"
               iyy="0.1" iyz="0.0"
               izz="0.1" />
    </inertial>-->
    <inertial>
      <origin xyz="3.0876154e-04 0.0000000e+00 -1.2176461e-04"/>
      <mass value="7.9119962e-02"/>
      <inertia ixx="1.2505234e-05" ixy="0.0" ixz="-1.7855208e-07" iyy="2.1898364e-05" iyz="0.0" izz="1.9267361e-05"/>
    </inertial>
  </link>
  <!-- Joint 1 -->
  <joint name="joint1" type="revolute">
    <parent link="link1"/>
    <child link="link2"/>
    <origin rpy="0 0 0" xyz="0.012 0.0 0.017"/>
    <axis xyz="0 0 1"/>
    <limit effort="1" lower="-2.82743338823" upper="3.14" velocity="4.8"/>
  </joint>
  <transmission name="tran1">
    <type>transmission_interface/SimpleTransmission</type>
    <joint name="joint1">
      <hardwareInterface>hardware_interface/PositionJointInterface</hardwareInterface>
    </joint>
    <actuator name="motor1">
      <hardwareInterface>hardware_interface/PositionJointInterface</hardwareInterface>
      <mechanicalReduction>1</mechanicalReduction>
    </actuator>
  </transmission>
  <!--  Link 2 -->
  <link name="link2">
    <visual>
      <origin rpy="0 0 0" xyz="0 0 0.018"/>
      <geometry>
        <mesh filename="meshes/chain_link2.stl" scale="0.001 0.001 0.001"/>
      </geometry>
      <material name="grey"/>
    </visual>
    <collision>
      <origin rpy="0 0 0" xyz="0 0 0.018"/>
      <geometry>
        <mesh filename="meshes/chain_link2.stl" scale="0.001 0.001 0.001"/>
      </geometry>
    </collision>
    <!--    <inertial>
      <origin xyz="0 0 0" />
      <mass value="0.098" />
      <inertia ixx="0.1" ixy="0.0" ixz="0.0"
               iyy="0.1" iyz="0.0"
               izz="0.1" />
    </inertial>-->
    <inertial>
      <origin xyz="-3.0184870e-04 5.4043684e-04 0.047433464"/>
      <mass value="9.8406837e-02"/>
      <inertia ixx="3.4543422e-05" ixy="-1.6031095e-08" ixz="-3.8375155e-07" iyy="3.2689329e-05" iyz="2.8511935e-08" izz="1.8850320e-05"/>
    </inertial>
  </link>
  <!--  Joint 2 -->
  <joint name="joint2" type="revolute">
    <parent link="link2"/>
    <child link="link3"/>
    <origin rpy="0 0 0" xyz="0.0 0.0 0.058"/>
    <axis xyz="0 1 0"/>
    <limit effort="1" lower="-1.79070781255" upper="1.57079632679" velocity="4.8"/>
  </joint>
  <transmission name="tran2">
    <type>transmission_interface/SimpleTransmission</type>
    <joint name="joint2">
      <hardwareInterface>hardware_interface/PositionJointInterface</hardwareInterface>
    </joint>
    <actuator name="motor2">
      <hardwareInterface>hardware_interface/PositionJointInterface</hardwareInterface>
      <mechanicalReduction>1</mechanicalReduction>
    </actuator>
  </transmission>
  <!--  Link 3 -->
  <link name="link3">
    <visual>
      <origin rpy="0 0 0" xyz="0 0 0"/>
      <geometry>
        <mesh filename="meshes/chain_link3.stl" scale="0.001 0.001 0.001"/>
      </geometry>
      <material name="grey"/>
    </visual>
    <collision>
      <origin rpy="0 0 0" xyz="0 0 0"/>
      <geometry>
        <mesh filename="meshes/chain_link3.stl" scale="0.001 0.001 0.001"/>
      </geometry>
    </collision>
    <!--    <inertial>
      <origin xyz="0 0 0" />
      <mass value="0.136" />
      <inertia ixx="0.1" ixy="0.0" ixz="0.0"
               iyy="0.1" iyz="0.0"
               izz="0.1" />
    </inertial>-->
    <inertial>
      <origin xyz="1.0308393e-02 3.7743363e-04 1.0170197e-01"/>
      <mass value="1.3850917e-01"/>
      <inertia ixx="3.3055381e-04" ixy="-9.7940978e-08" ixz="-3.8505711e-05" iyy="3.4290447e-04" iyz="-1.5717516e-06" izz="6.0346498e-05"/>
    </inertial>
  </link>
  <!--  Joint 3 -->
  <joint name="joint3" type="revolute">
    <parent link="link3"/>
    <child link="link4"/>
    <origin rpy="0 0 0" xyz="0.024 0 0.128"/>
    <axis xyz="0 1 0"/>
    <limit effort="1" lower="-0.942477796077" upper="1.38230076758" velocity="4.8"/>
  </joint>
  <transmission name="tran3">
    <type>transmission_interface/SimpleTransmission</type>
    <joint name="joint3">
      <hardwareInterface>hardware_interface/PositionJointInterface</hardwareInterface>
    </joint>
    <actuator name="motor3">
      <hardwareInterface>hardware_interface/PositionJointInterface</hardwareInterface>
      <mechanicalReduction>1</mechanicalReduction>
    </actuator>
  </transmission>
  <!--  Link 4 -->
  <link name="link4">
    <visual>
      <origin rpy="0 0 0" xyz="0 0 0"/>
      <geometry>
        <mesh filename="meshes/chain_link4.stl" scale="0.001 0.001 0.001"/>
      </geometry>
      <material name="grey"/>
    </visual>
    <collision>
      <origin rpy="0 0 0" xyz="0 0 0"/>
      <geometry>
        <mesh filename="meshes/chain_link4.stl" scale="0.001 0.001 0.001"/>
      </geometry>
    </collision>
    <!--    <inertial>
      <origin xyz="0 0 0" />
      <mass value="0.131" />
      <inertia ixx="0.1" ixy="0.0" ixz="0.0"
               iyy="0.1" iyz="0.0"
               izz="0.1" />
    </inertial>-->
    <inertial>
      <origin xyz="9.0909590e-02 3.8929816e-04 2.2413279e-04"/>
      <mass value="1.3274562e-01"/>
      <inertia ixx="3.0654178e-05" ixy="-1.2764155e-06" ixz="-2.6874417e-07" iyy="2.4230292e-04" iyz="1.1559550e-08" izz="2.5155057e-04"/>
    </inertial>
  </link>
  <!--  Joint 4 -->
  <joint name="joint4" type="revolute">
    <parent link="link4"/>
    <child link="link5"/>
    <!-- <origin rpy="0 0 0" xyz="0.124 0.0 0.0"/> -->
    <origin rpy="0 0 0" xyz="0.12 0.0 0.0"/>
    <axis xyz="0 1 0"/>
    <limit effort="1" lower="-1.79070781255" upper="2.04203522483" velocity="4.8"/>
  </joint>
  <transmission name="tran4">
    <type>transmission_interface/SimpleTransmission</type>
    <joint name="joint4">
      <hardwareInterface>hardware_interface/PositionJointInterface</hardwareInterface>
    </joint>
    <actuator name="motor4">
      <hardwareInterface>hardware_interface/PositionJointInterface</hardwareInterface>
      <mechanicalReduction>1</mechanicalReduction>
    </actuator>
  </transmission>
  <!--  Link 5 (spherical)-->
  <link name="link5">
    <visual>
      <origin rpy="0 1.57 0" xyz="0.05 0 0"/>
      <geometry>
  	<cylinder radius=".025" length=".1" />
      </geometry>
      <material name="grey"/>
    </visual>
    <collision>
      <origin rpy="0 0 0" xyz="0 0 0"/>
      <geometry>
  	<cylinder radius=".025" length=".1"/>
      </geometry>
    </collision>
    <!--    <inertial>
      <origin xyz="0 0 0" />
      <mass value="0.141" />
      <inertia ixx="0.1" ixy="0.0" ixz="0.0"
               iyy="0.1" iyz="0.0"
               izz="0.1" />
    </inertial>-->
    <inertial>
      <origin xyz="4.4206755e-02 3.6839985e-07 8.9142216e-03"/>
      <mass value="1.4327573e-01"/>
      <inertia ixx="8.0870749e-05" ixy="0.0" ixz="-1.0157896e-06" iyy="7.5980465e-05" iyz="0.0" izz="9.3127351e-05"/>
    </inertial>
  </link>
</robot>
