<?xml version="1.0" ?>
<!-- =================================================================================== -->
<!-- |    This document was autogenerated by xacro from open_manipulator_with_tb3_waffle_pi.urdf.xacro | -->
<!-- |    EDITING THIS FILE BY HAND IS NOT RECOMMENDED                                 | -->
<!-- =================================================================================== -->
<!-- Open_Manipulator Chain -->
<robot name="om_with_tb3" xmlns:xacro="http://ros.org/wiki/xacro">
  <!-- Init colour -->
  <material name="black">
    <color rgba="0.0 0.0 0.0 1.0"/>
  </material>
  <material name="dark">
    <color rgba="0.3 0.3 0.3 1.0"/>
  </material>
  <material name="light_black">
    <color rgba="0.4 0.4 0.4 1.0"/>
  </material>
  <material name="blue">
    <color rgba="0.0 0.0 0.8 1.0"/>
  </material>
  <material name="green">
    <color rgba="0.0 0.8 0.0 1.0"/>
  </material>
  <material name="grey">
    <color rgba="0.5 0.5 0.5 1.0"/>
  </material>
  <material name="orange">
    <color rgba="1.0 0.423529411765 0.0392156862745 1.0"/>
  </material>
  <material name="brown">
    <color rgba="0.870588235294 0.811764705882 0.764705882353 1.0"/>
  </material>
  <material name="red">
    <color rgba="0.8 0.0 0.0 1.0"/>
  </material>
  <material name="white">
    <color rgba="1.0 1.0 1.0 1.0"/>
  </material>
  
  <link name="base_link">
    <visual>
      <origin rpy="0 0 0" xyz="-0.064 0 0.0"/>
      <geometry>
        <mesh filename="meshes/bases/waffle_pi_base_for_open_manipulator.stl" scale="0.001 0.001 0.001"/>
      </geometry>
      <material name="light_black"/>
    </visual>
    <collision>
      <origin rpy="0 0 0" xyz="-0.064 0 0.047"/>
      <geometry>
        <box size="0.266 0.266 0.094"/>
      </geometry>
    </collision>
    <inertial>
      <origin rpy="0 0 0" xyz="-.1 0 -.1"/>
      <!-- <origin rpy="0 0 0" xyz="0 0 0"/> -->
      <mass value="10.3729096e+00"/>
      <!-- <mass value="1.3729096e+00"/> -->
      <inertia ixx="8.7002718e-03" ixy="-4.7576583e-05" ixz="1.1160499e-04" iyy="8.6195418e-03" iyz="-3.5422299e-06" izz="1.4612727e-02"/>
    </inertial>
  </link>
  <!-- <gazebo reference="base_link"> -->
  <!--   <material>Gazebo/DarkGrey</material> -->
  <!-- </gazebo> -->

  <joint name="wheel_left_joint" type="continuous">
    <parent link="base_link"/>
    <child link="wheel_left_link"/>
    <origin rpy="-1.57 0 0" xyz="0.0 0.144 0.023"/>
    <axis xyz="0 0 1"/>
  </joint>
  <link name="wheel_left_link">
    <contact>
      <lateral_friction value="1.0"/>
      <rolling_friction value="0.0"/>
      <stiffness value="30000"/>
      <damping value="1000"/>
    </contact>
    <visual>
      <origin rpy="1.57 0 0" xyz="0 0 0"/>
      <geometry>
        <mesh filename="meshes/wheels/left_tire.stl" scale="0.001 0.001 0.001"/>
      </geometry>
      <material name="dark"/>
    </visual>
    <collision>
      <origin rpy="0 0 0" xyz="0 0 0"/>
      <geometry>
        <cylinder length="0.018" radius="0.033"/>
      </geometry>
    </collision>
    <inertial>
      <origin xyz="0 0 0"/>
      <mass value="2.8498940e-02"/>
      <inertia ixx="1.1175580e-05" ixy="-4.2369783e-11" ixz="-5.9381719e-09" iyy="1.1192413e-05" iyz="-1.4400107e-11" izz="2.0712558e-05"/>
    </inertial>
  </link>
  <!-- <gazebo reference="wheel_left_link"> -->
  <!--   <mu1>0.1</mu1> -->
  <!--   <mu2>0.1</mu2> -->
  <!--   <kp>500000.0</kp> -->
  <!--   <kd>10.0</kd> -->
  <!--   <minDepth>0.001</minDepth> -->
  <!--   <maxVel>0.1</maxVel> -->
  <!--   <fdir1>1 0 0</fdir1> -->
  <!--   <material>Gazebo/FlatBlack</material> -->
  <!-- </gazebo> -->
    
  <joint name="wheel_right_joint" type="continuous">
    <parent link="base_link"/>
    <child link="wheel_right_link"/>
    <origin rpy="-1.57 0 0" xyz="0.0 -0.144 0.023"/>
    <axis xyz="0 0 1"/>
  </joint>
  <link name="wheel_right_link">
    <contact>
      <lateral_friction value="1.0"/>
      <rolling_friction value="0.0"/>
      <stiffness value="30000"/>
      <damping value="1000"/>
    </contact>
    <visual>
      <origin rpy="1.57 0 0" xyz="0 0 0"/>
      <geometry>
        <mesh filename="meshes/wheels/right_tire.stl" scale="0.001 0.001 0.001"/>
      </geometry>
      <material name="dark"/>
    </visual>
    <collision>
      <origin rpy="0 0 0" xyz="0 0.001 0"/>
      <geometry>
        <cylinder length="0.018" radius="0.033"/>
      </geometry>
    </collision>
    <inertial>
      <origin xyz="0 0 0"/>
      <mass value="2.8498940e-02"/>
      <inertia ixx="1.1175580e-05" ixy="-4.2369783e-11" ixz="-5.9381719e-09" iyy="1.1192413e-05" iyz="-1.4400107e-11" izz="2.0712558e-05"/>
    </inertial>
  </link>
  <!-- <gazebo reference="wheel_right_link"> -->
  <!--   <mu1>0.1</mu1> -->
  <!--   <mu2>0.1</mu2> -->
  <!--   <kp>500000.0</kp> -->
  <!--   <kd>10.0</kd> -->
  <!--   <minDepth>0.001</minDepth> -->
  <!--   <maxVel>0.1</maxVel> -->
  <!--   <fdir1>1 0 0</fdir1> -->
  <!--   <material>Gazebo/FlatBlack</material> -->
  <!-- </gazebo> -->
    
  <joint name="caster_back_right_joint" type="fixed">
  <!-- <joint name="caster_back_right_joint" type="floating"> -->
    <parent link="base_link"/>
    <child link="caster_back_right_link"/>
    <origin rpy="-1.57 0 0" xyz="-0.177 -0.064 -0.004"/>
  </joint>
  <link name="caster_back_right_link">
    <contact>
      <lateral_friction value="0.0"/>
      <rolling_friction value="0.0"/>
      <stiffness value="30000"/>
      <damping value="1000"/>
    </contact>
    <collision>
      <origin rpy="0 0 0" xyz="0 0.001 0"/>
      <geometry>
	<!-- <box size="0.030 0.009 0.020"/> -->
        <sphere radius=".007"/>
      </geometry>
    </collision>
    <inertial>
      <origin xyz="0 0 0"/>
      <mass value="0.005"/>
      <inertia ixx="0.001" ixy="0.0" ixz="0.0" iyy="0.001" iyz="0.0" izz="0.001"/>
    </inertial>
  </link>
  <!-- <gazebo reference="caster_back_right_link"> -->
  <!--   <mu1>0.1</mu1> -->
  <!--   <mu2>0.1</mu2> -->
  <!--   <kp>1000000.0</kp> -->
  <!--   <kd>100.0</kd> -->
  <!--   <minDepth>0.001</minDepth> -->
  <!--   <maxVel>1.0</maxVel> -->
  <!--   <material>Gazebo/FlatBlack</material> -->
  <!-- </gazebo> -->
    
  <!-- <joint name="caster_back_left_joint" type="floating"> -->
  <joint name="caster_back_left_joint" type="fixed">
    <parent link="base_link"/>
    <child link="caster_back_left_link"/>
    <origin rpy="-1.57 0 0" xyz="-0.177 0.064 -0.004"/>
  </joint>
  <link name="caster_back_left_link">
    <contact>
      <lateral_friction value="0.0"/>
      <rolling_friction value="0.0"/>
      <stiffness value="30000"/>
      <damping value="1000"/>
    </contact>
    <collision>
      <origin rpy="0 0 0" xyz="0 0.001 0"/>
      <geometry>
	<sphere radius=".007"/>
        <!-- <box size="0.030 0.009 0.020"/> -->
      </geometry>
    </collision>
    <inertial>
      <origin xyz="0 0 0"/>
      <mass value="0.005"/>
      <inertia ixx="0.001" ixy="0.0" ixz="0.0" iyy="0.001" iyz="0.0" izz="0.001"/>
    </inertial>
  </link>
  <!-- <gazebo reference="caster_back_left_link"> -->
  <!--   <mu1>0.1</mu1> -->
  <!--   <mu2>0.1</mu2> -->
  <!--   <kp>1000000.0</kp> -->
  <!--   <kd>100.0</kd> -->
  <!--   <minDepth>0.001</minDepth> -->
  <!--   <maxVel>1.0</maxVel> -->
  <!--   <material>Gazebo/FlatBlack</material> -->
  <!-- </gazebo> -->
    
  <joint name="imu_joint" type="fixed">
    <parent link="base_link"/>
    <child link="imu_link"/>
    <origin rpy="0 0 0" xyz="0.0 0 0.068"/>
  </joint>
  <link name="imu_link"/>
  <joint name="scan_joint" type="fixed">
    <parent link="base_link"/>
    <child link="base_scan"/>
    <origin rpy="0 0 0" xyz="-0.024 0 0.122"/>
  </joint>
  <link name="base_scan">
    <visual>
      <origin rpy="0 0 0" xyz="0 0 0.0"/>
      <geometry>
        <mesh filename="meshes/sensors/lds.stl" scale="0.001 0.001 0.001"/>
      </geometry>
      <material name="dark"/>
    </visual>
    <collision>
      <origin rpy="0 0 0" xyz="0.015 0 -0.0065"/>
      <geometry>
        <cylinder length="0.0315" radius="0.045"/>
      </geometry>
    </collision>
    <inertial>
      <mass value="0.114"/>
      <origin xyz="0 0 0"/>
      <inertia ixx="0.001" ixy="0.0" ixz="0.0" iyy="0.001" iyz="0.0" izz="0.001"/>
    </inertial>
  </link>
  <joint name="camera_joint" type="fixed">
    <origin rpy="0 0 0" xyz="0.073 -0.011 0.084"/>
    <parent link="base_link"/>
    <child link="camera_link"/>
  </joint>
  <link name="camera_link">
    <collision>
      <origin rpy="0 0 0" xyz="0.005 0.011 0.013"/>
      <geometry>
        <box size="0.015 0.030 0.027"/>
      </geometry>
    </collision>
  </link>
  <joint name="camera_rgb_joint" type="fixed">
    <origin rpy="0 0 0" xyz="0.003 0.011 0.009"/>
    <parent link="camera_link"/>
    <child link="camera_rgb_frame"/>
  </joint>
  <link name="camera_rgb_frame"/>
  <joint name="camera_rgb_optical_joint" type="fixed">
    <origin rpy="-1.57 0 -1.57" xyz="0 0 0"/>
    <parent link="camera_rgb_frame"/>
    <child link="camera_rgb_optical_frame"/>
  </joint>
  <link name="camera_rgb_optical_frame"/>
</robot>
